#VRML_SIM R2025a utf8

EXTERNPROTO "https://raw.githubusercontent.com/cyberbotics/webots/R2023b/projects/objects/backgrounds/protos/TexturedBackground.proto"
EXTERNPROTO "https://raw.githubusercontent.com/cyberbotics/webots/R2023b/projects/objects/backgrounds/protos/TexturedBackgroundLight.proto"
EXTERNPROTO "https://raw.githubusercontent.com/cyberbotics/webots/R2023b/projects/objects/floors/protos/RectangleArena.proto"
EXTERNPROTO "https://raw.githubusercontent.com/cyberbotics/webots/R2025a/projects/objects/balls/protos/Ball.proto"

WorldInfo {
}
Viewpoint {
  orientation 0.14565134932952725 -0.11978958769458949 -0.9820570956509853 4.455502451456638
  position 3.9457715943896243 -11.090312791986024 3.773855800341779
}
TexturedBackground {
}
TexturedBackgroundLight {
}
RectangleArena {
  floorSize 2 2
  wallHeight 0.2
}
Ball {
  hidden linearVelocity_0 0.060879487109817866 0.11567952086030617 0.00010677895287375315
  hidden angularVelocity_0 -1.1491603243346962 0.6047640722735275 0.013887152443398294
  translation 0.6775461127885727 0.5606024396621461 0.09991331967045734
  rotation 0.7085095040042511 -0.5622751357266139 0.4264515851527204 -1.5653530496600272
  color 1 0 0
  radius 0.1
}
Robot {
  translation 0.5461877451151531 0.4339204064983282 -0.0004393612897624147
  rotation 1.3840115405314456e-05 -2.2868999516891464e-06 0.9999999999016105 1.0548545142336678
  children [
    Solid {
      translation 0 0 0.045
      children [
        Shape {
          appearance PBRAppearance {
            baseColor 0.05 0.05 0.05
            roughness 0.2
            metalness 0.9
          }
          geometry Box {
            size 0.14 0.11 0.002
          }
        }
      ]
      name "solid(1)"
      boundingObject Box {
        size 0.14 0.11 0.002
      }
      physics Physics {
        mass 0.2
      }
    }
    Pose {
      translation 0.06 0.05 0.065
      children [
        DEF STANDOFF Shape {
          appearance PBRAppearance {
            baseColor 0.8 0.6 0.2
          }
          geometry Cylinder {
            height 0.04
            radius 0.003
          }
        }
      ]
    }
    Pose {
      translation 0.06 -0.05 0.065
      children [
        USE STANDOFF
      ]
    }
    Pose {
      translation -0.06 0.05 0.065
      children [
        USE STANDOFF
      ]
    }
    Pose {
      translation -0.06 -0.05 0.065
      children [
        USE STANDOFF
      ]
    }
    Solid {
      translation 0 0 0.085
      children [
        Shape {
          appearance PBRAppearance {
            baseColor 0.05 0.05 0.05
            roughness 0.2
            metalness 0.9
          }
          geometry Box {
            size 0.14 0.11 0.002
          }
        }
      ]
      boundingObject Box {
        size 0.14 0.11 0.002
      }
      physics Physics {
        mass 0.1
      }
    }
    Pose {
      translation -0.05 -3.67318e-08 0.065
      rotation 0 0 1 1.5708
      children [
        Shape {
          appearance PBRAppearance {
            baseColor 0.1 0.2 0.9
            metalness 0.1
          }
          geometry Cylinder {
            height 0.04
            radius 0.018
          }
        }
        Pose {
          translation 0 -0.018 -0.018
          children [
            Shape {
              appearance PBRAppearance {
                baseColor 0.1 0.1 0.1
              }
              geometry Box {
                size 0.06 0.01 0.005
              }
            }
          ]
        }
      ]
    }
    Pose {
      translation 0.01 0 0.087
      children [
        Shape {
          appearance PBRAppearance {
            baseColor 0 0.35 0
            roughness 0.6
          }
          geometry Box {
            size 0.1 0.08 0.0015
          }
        }
        Pose {
          translation 0 0 0.013
          children [
            Shape {
              appearance PBRAppearance {
                baseColor 0.75 0.75 0.75
                metalness 0.9
              }
              geometry Box {
                size 0.06 0.04 0.025
              }
            }
          ]
        }
        Pose {
          translation 0.045 -0.015 0.006
          children [
            DEF USB_PORT Shape {
              appearance PBRAppearance {
                baseColor 0.8 0.8 0.8
              }
              geometry Box {
                size 0.01 0.015 0.01
              }
            }
          ]
        }
        Pose {
          translation 0.045 0.015 0.006
          children [
            USE USB_PORT
          ]
        }
        Pose {
          translation 0.045 0.035 0.008
          children [
            Shape {
              appearance PBRAppearance {
                baseColor 0.8 0.8 0.8
              }
              geometry Box {
                size 0.01 0.02 0.015
              }
            }
          ]
        }
      ]
    }
    Pose {
      translation -0.03 0 0.086
      children [
        Pose {
          translation 0 0 0.025
          children [
            Shape {
              appearance PBRAppearance {
                baseColor 0.1 0.1 0.1
              }
              geometry Cylinder {
                height 0.05
                radius 0.01
              }
            }
          ]
        }
        Pose {
          translation 0 0 0.05
          children [
            Lidar {
              rotation 0 0 1 -3.010695613280012
              children [
                Shape {
                  appearance PBRAppearance {
                    baseColor 0.1 0.1 0.1
                    roughness 0.6
                  }
                  geometry Cylinder {
                    height 0.02
                    radius 0.03
                  }
                }
                Pose {
                  translation 0 0 0.025
                  children [
                    Shape {
                      appearance PBRAppearance {
                        baseColor 0.05 0.05 0.05
                        roughness 0.5
                      }
                      geometry Cylinder {
                        height 0.02
                        radius 0.03
                      }
                    }
                    Pose {
                      translation 0.025 0.005 0
                      children [
                        Shape {
                          appearance PBRAppearance {
                            baseColor 0.1 0.1 0.8
                            metalness 0.5
                            emissiveColor 0 0 0.1
                          }
                          geometry Box {
                            size 0.01 0.01 0.01
                          }
                        }
                      ]
                    }
                    Pose {
                      translation 0.025 -0.005 0
                      children [
                        Shape {
                          appearance PBRAppearance {
                            baseColor 0.1 0.1 0.8
                            metalness 0.5
                          }
                          geometry Box {
                            size 0.01 0.01 0.01
                          }
                        }
                      ]
                    }
                  ]
                }
              ]
              horizontalResolution 720
              fieldOfView 6.28318
              numberOfLayers 5
              minRange 0.12
              maxRange 8
              noise 0.005
            }
          ]
        }
      ]
    }
    Pose {
      translation 0.065 0 0.086
      children [
        Pose {
          translation -0.005 0 0.005
          children [
            Shape {
              appearance PBRAppearance {
                baseColor 0.1 0.1 0.1
              }
              geometry Box {
                size 0.01 0.03 0.01
              }
            }
          ]
        }
        Pose {
          translation 0 0 0.015
          children [
            Camera {
              rotation 0.579145126877391 0.5753141260381066 0.5775851265356307 0.000395586
              children [
                Shape {
                  appearance PBRAppearance {
                    baseColor 0 0.3 0
                  }
                  geometry Box {
                    size 0.005 0.03 0.03
                  }
                }
                Pose {
                  translation 0.005 0 0
                  rotation 0 0 1 1.5708
                  children [
                    Shape {
                      appearance PBRAppearance {
                        baseColor 0.1 0.1 0.1
                        roughness 0.1
                      }
                      geometry Cylinder {
                        height 0.01
                        radius 0.008
                      }
                    }
                  ]
                }
              ]
              fieldOfView 2.5
              width 1280
              height 720
            }
          ]
        }
      ]
    }
    HingeJoint {
      jointParameters HingeJointParameters {
        position 917.5938204756893
        axis 0 1 0
        anchor 0 0.07 0.0325
      }
      device [
        RotationalMotor {
          name "left_wheel_motor"
          maxVelocity 15
          maxTorque 0.5
        }
        PositionSensor {
          name "left_wheel_sensor"
        }
      ]
      endPoint Solid {
        translation 0 0.075 0.0325
        rotation 0.9847252371027306 0.12311802478785026 -0.12311847702643733 1.586192015591222
        children [
          Shape {
            appearance PBRAppearance {
              baseColor 0.95 0.8 0.1
              roughness 0.4
              metalness 0.1
            }
            geometry Cylinder {
              height 0.026
              radius 0.028
            }
          }
          Shape {
            appearance PBRAppearance {
              baseColor 0.15 0.15 0.15
              roughness 0.9
              metalness 0
            }
            geometry Cylinder {
              height 0.025
              radius 0.0325
            }
          }
          Pose {
            translation 0 0.014 0
            children [
              Shape {
                appearance PBRAppearance {
                  baseColor 0.7 0.7 0.7
                }
                geometry Cylinder {
                  height 0.005
                  radius 0.004
                }
              }
            ]
          }
        ]
        name "left wheel"
        boundingObject Cylinder {
          height 0.026
          radius 0.0325
        }
        physics Physics {
          density -1
          mass 0.06
        }
        linearVelocity 0.06259008892026435 0.11013699873298566 2.328464861514874e-07
        angularVelocity -3.4017782208588443 1.933173335281985 0.038638362400278584
      }
    }
    HingeJoint {
      jointParameters HingeJointParameters {
        position 843.1092810726656
        axis 0 1 0
        anchor 0 -0.07 0.0325
      }
      device [
        RotationalMotor {
          name "right_wheel_motor"
          maxVelocity 15
          maxTorque 0.5
        }
        PositionSensor {
          name "right_wheel_sensor"
        }
      ]
      endPoint Solid {
        translation 0 -0.075 0.0325
        rotation 0.7326280163245985 0.4812766813701272 -0.48127844920133367 1.8770161143043131
        children [
          Shape {
            appearance PBRAppearance {
              baseColor 0.95 0.8 0.1
              roughness 0.4
              metalness 0.1
            }
            geometry Cylinder {
              height 0.026
              radius 0.028
            }
          }
          Shape {
            appearance PBRAppearance {
              baseColor 0.15 0.15 0.15
              roughness 0.9
              metalness 0
            }
            geometry Cylinder {
              height 0.025
              radius 0.0325
            }
          }
          Pose {
            translation 0 -0.014 0
            children [
              Shape {
                appearance PBRAppearance {
                  baseColor 0.7 0.7 0.7
                }
                geometry Cylinder {
                  height 0.005
                  radius 0.004
                }
              }
            ]
          }
        ]
        name "right wheel"
        boundingObject Cylinder {
          height 0.026
          radius 0.0325
        }
        physics Physics {
          density -1
          mass 0.06
        }
        linearVelocity 0.06538623346915459 0.11506039595214253 -2.175589108570176e-07
        angularVelocity -3.5535611484365073 2.019469105122522 0.03868566686181882
      }
    }
    Solid {
      translation -0.057 0 0.01
      children [
        Pose {
          translation 0 0 0.017
          children [
            Shape {
              appearance PBRAppearance {
                baseColor 0.5 0.5 0.5
                metalness 0.8
              }
              geometry Cylinder {
                height 0.034
                radius 0.012
              }
            }
          ]
        }
        DEF CASTER_SHAPE Shape {
          appearance PBRAppearance {
            baseColor 0.8 0.8 0.8
            roughness 0.1
          }
          geometry Sphere {
            radius 0.01
          }
        }
      ]
      name "rear_caster"
      boundingObject USE CASTER_SHAPE
      physics Physics {
        mass 0.02
      }
    }
    Solid {
      translation 0.057 0 0.01
      children [
        Pose {
          translation 0 0 0.017
          children [
            Shape {
              appearance PBRAppearance {
                baseColor 0.5 0.5 0.5
                metalness 0.8
              }
              geometry Cylinder {
                height 0.034
                radius 0.012
              }
            }
          ]
        }
        USE CASTER_SHAPE
      ]
      name "front_caster"
      boundingObject USE CASTER_SHAPE
      physics Physics {
        mass 0.02
      }
    }
  ]
  name "JetBot"
  model "Waveshare JetBot ROS AI Kit"
  boundingObject Group {
    children [
      Pose {
        translation 0 0 0.06
        children [
          Box {
            size 0.15 0.11 0.08
          }
        ]
      }
    ]
  }
  physics Physics {
    density -1
    mass 1.2
    centerOfMass [
      0 0 0.05
    ]
  }
  controller "robot_test"
  linearVelocity 0.06398829547522993 0.11259878554277471 -1.179990558824934e-08
  angularVelocity -2.581751728195811e-06 5.467891436850045e-06 0.0377532198794394
}
