#VRML_SIM R2025a utf8

EXTERNPROTO "https://raw.githubusercontent.com/cyberbotics/webots/R2023b/projects/objects/backgrounds/protos/TexturedBackground.proto"
EXTERNPROTO "https://raw.githubusercontent.com/cyberbotics/webots/R2023b/projects/objects/backgrounds/protos/TexturedBackgroundLight.proto"
EXTERNPROTO "https://raw.githubusercontent.com/cyberbotics/webots/R2023b/projects/objects/floors/protos/RectangleArena.proto"

WorldInfo {
}
Viewpoint {
  orientation 0.01202692142043798 -0.9985407867332297 -0.05264646608585914 5.506065514674408
  position -0.3510857293721705 0.015900039983473356 0.3923013681618275
}
TexturedBackground {
}
TexturedBackgroundLight {
}
RectangleArena {
  wallHeight 0.2
}
Robot {
  translation -0.09268744235460125 -0.007425411167419894 -0.0004528651591661978
  rotation 6.379808322758485e-05 8.078137153159771e-05 0.9999999947020872 -3.054414322756615
  children [
    Solid {
      translation 0 0 0.045
      children [
        Shape {
          appearance PBRAppearance {
            baseColor 0.05 0.05 0.05
            roughness 0.2
            metalness 0.9
          }
          geometry Box {
            size 0.14 0.11 0.002
          }
        }
      ]
      name "solid(1)"
      boundingObject Box {
        size 0.14 0.11 0.002
      }
      physics Physics {
        mass 0.2
      }
    }
    Pose {
      translation 0.06 0.05 0.065
      children [
        DEF STANDOFF Shape {
          appearance PBRAppearance {
            baseColor 0.8 0.6 0.2
          }
          geometry Cylinder {
            height 0.04
            radius 0.003
          }
        }
      ]
    }
    Pose {
      translation 0.06 -0.05 0.065
      children [
        USE STANDOFF
      ]
    }
    Pose {
      translation -0.06 0.05 0.065
      children [
        USE STANDOFF
      ]
    }
    Pose {
      translation -0.06 -0.05 0.065
      children [
        USE STANDOFF
      ]
    }
    Solid {
      translation 0 0 0.085
      children [
        Shape {
          appearance PBRAppearance {
            baseColor 0.05 0.05 0.05
            roughness 0.2
            metalness 0.9
          }
          geometry Box {
            size 0.14 0.11 0.002
          }
        }
      ]
      boundingObject Box {
        size 0.14 0.11 0.002
      }
      physics Physics {
        mass 0.1
      }
    }
    Pose {
      translation -0.05 -3.67318e-08 0.065
      rotation 0 0 1 1.5708
      children [
        Shape {
          appearance PBRAppearance {
            baseColor 0.1 0.2 0.9
            metalness 0.1
          }
          geometry Cylinder {
            height 0.04
            radius 0.018
          }
        }
        Pose {
          translation 0 -0.018 -0.018
          children [
            Shape {
              appearance PBRAppearance {
                baseColor 0.1 0.1 0.1
              }
              geometry Box {
                size 0.06 0.01 0.005
              }
            }
          ]
        }
      ]
    }
    Pose {
      translation 0.01 0 0.087
      children [
        Shape {
          appearance PBRAppearance {
            baseColor 0 0.35 0
            roughness 0.6
          }
          geometry Box {
            size 0.1 0.08 0.0015
          }
        }
        Pose {
          translation 0 0 0.013
          children [
            Shape {
              appearance PBRAppearance {
                baseColor 0.75 0.75 0.75
                metalness 0.9
              }
              geometry Box {
                size 0.06 0.04 0.025
              }
            }
          ]
        }
        Pose {
          translation 0.045 -0.015 0.006
          children [
            DEF USB_PORT Shape {
              appearance PBRAppearance {
                baseColor 0.8 0.8 0.8
              }
              geometry Box {
                size 0.01 0.015 0.01
              }
            }
          ]
        }
        Pose {
          translation 0.045 0.015 0.006
          children [
            USE USB_PORT
          ]
        }
        Pose {
          translation 0.045 0.035 0.008
          children [
            Shape {
              appearance PBRAppearance {
                baseColor 0.8 0.8 0.8
              }
              geometry Box {
                size 0.01 0.02 0.015
              }
            }
          ]
        }
      ]
    }
    Pose {
      translation -0.03 0 0.086
      children [
        Pose {
          translation 0 0 0.025
          children [
            Shape {
              appearance PBRAppearance {
                baseColor 0.1 0.1 0.1
              }
              geometry Cylinder {
                height 0.05
                radius 0.01
              }
            }
          ]
        }
        Pose {
          translation 0 0 0.05
          children [
            Lidar {
              rotation 0 0 1 -3.010695613280012
              children [
                Shape {
                  appearance PBRAppearance {
                    baseColor 0.1 0.1 0.1
                    roughness 0.6
                  }
                  geometry Cylinder {
                    height 0.02
                    radius 0.03
                  }
                }
                Pose {
                  translation 0 0 0.025
                  children [
                    Shape {
                      appearance PBRAppearance {
                        baseColor 0.05 0.05 0.05
                        roughness 0.5
                      }
                      geometry Cylinder {
                        height 0.02
                        radius 0.03
                      }
                    }
                    Pose {
                      translation 0.025 0.005 0
                      children [
                        Shape {
                          appearance PBRAppearance {
                            baseColor 0.1 0.1 0.8
                            metalness 0.5
                            emissiveColor 0 0 0.1
                          }
                          geometry Box {
                            size 0.01 0.01 0.01
                          }
                        }
                      ]
                    }
                    Pose {
                      translation 0.025 -0.005 0
                      children [
                        Shape {
                          appearance PBRAppearance {
                            baseColor 0.1 0.1 0.8
                            metalness 0.5
                          }
                          geometry Box {
                            size 0.01 0.01 0.01
                          }
                        }
                      ]
                    }
                  ]
                }
              ]
              horizontalResolution 720
              fieldOfView 6.28318
              numberOfLayers 5
              minRange 0.12
              maxRange 8
              noise 0.005
            }
          ]
        }
      ]
    }
    Pose {
      translation 0.065 0 0.086
      children [
        Pose {
          translation -0.005 0 0.005
          children [
            Shape {
              appearance PBRAppearance {
                baseColor 0.1 0.1 0.1
              }
              geometry Box {
                size 0.01 0.03 0.01
              }
            }
          ]
        }
        Pose {
          translation 0 0 0.015
          children [
            Camera {
              rotation 0.579145126877391 0.5753141260381066 0.5775851265356307 0.000395586
              children [
                Shape {
                  appearance PBRAppearance {
                    baseColor 0 0.3 0
                  }
                  geometry Box {
                    size 0.005 0.03 0.03
                  }
                }
                Pose {
                  translation 0.005 0 0
                  rotation 0 0 1 1.5708
                  children [
                    Shape {
                      appearance PBRAppearance {
                        baseColor 0.1 0.1 0.1
                        roughness 0.1
                      }
                      geometry Cylinder {
                        height 0.01
                        radius 0.008
                      }
                    }
                  ]
                }
              ]
              fieldOfView 2.5
              width 1280
              height 720
            }
          ]
        }
      ]
    }
    HingeJoint {
      jointParameters HingeJointParameters {
        position 751.3060091364416
        axis 0 1 0
        anchor 0 0.07 0.0325
      }
      device [
        RotationalMotor {
          name "left_wheel_motor"
          maxVelocity 15
          maxTorque 0.5
        }
        PositionSensor {
          name "left_wheel_sensor"
        }
      ]
      endPoint Solid {
        translation 0 0.075 0.0325
        rotation 0.16526259662596357 -0.6973824995197808 0.6973850611534399 2.8140293455090006
        children [
          Shape {
            appearance PBRAppearance {
              baseColor 0.95 0.8 0.1
              roughness 0.4
              metalness 0.1
            }
            geometry Cylinder {
              height 0.026
              radius 0.028
            }
          }
          Shape {
            appearance PBRAppearance {
              baseColor 0.15 0.15 0.15
              roughness 0.9
              metalness 0
            }
            geometry Cylinder {
              height 0.025
              radius 0.0325
            }
          }
          Pose {
            translation 0 0.014 0
            children [
              Shape {
                appearance PBRAppearance {
                  baseColor 0.7 0.7 0.7
                }
                geometry Cylinder {
                  height 0.005
                  radius 0.004
                }
              }
            ]
          }
        ]
        name "left wheel"
        boundingObject Cylinder {
          height 0.026
          radius 0.0325
        }
        physics Physics {
          density -1
          mass 0.06
        }
        linearVelocity -0.16189962324265075 -0.014172964758713895 1.6940418171374512e-05
        angularVelocity 0.43687734392175387 -4.981929707973617 0.0009616330817035158
      }
    }
    HingeJoint {
      jointParameters HingeJointParameters {
        position 567.9283547127092
        axis 0 1 0
        anchor 0 -0.07 0.0325
      }
      device [
        RotationalMotor {
          name "right_wheel_motor"
          maxVelocity 15
          maxTorque 0.5
        }
        PositionSensor {
          name "right_wheel_sensor"
        }
      ]
      endPoint Solid {
        translation 0 -0.075 0.0325
        rotation 0.24989278121941913 0.6846715103127075 -0.6846740252562088 2.6518388839242095
        children [
          Shape {
            appearance PBRAppearance {
              baseColor 0.95 0.8 0.1
              roughness 0.4
              metalness 0.1
            }
            geometry Cylinder {
              height 0.026
              radius 0.028
            }
          }
          Shape {
            appearance PBRAppearance {
              baseColor 0.15 0.15 0.15
              roughness 0.9
              metalness 0
            }
            geometry Cylinder {
              height 0.025
              radius 0.0325
            }
          }
          Pose {
            translation 0 -0.014 0
            children [
              Shape {
                appearance PBRAppearance {
                  baseColor 0.7 0.7 0.7
                }
                geometry Cylinder {
                  height 0.005
                  radius 0.004
                }
              }
            ]
          }
        ]
        name "right wheel"
        boundingObject Cylinder {
          height 0.026
          radius 0.0325
        }
        physics Physics {
          density -1
          mass 0.06
        }
        linearVelocity -0.1618983491469177 -0.014196721980877252 0.00020229929780066338
        angularVelocity 0.4368808170873311 -4.981929456792713 0.0009598699735893198
      }
    }
    Solid {
      translation -0.057 0 0.01
      children [
        Pose {
          translation 0 0 0.017
          children [
            Shape {
              appearance PBRAppearance {
                baseColor 0.5 0.5 0.5
                metalness 0.8
              }
              geometry Cylinder {
                height 0.034
                radius 0.012
              }
            }
          ]
        }
        DEF CASTER_SHAPE Shape {
          appearance PBRAppearance {
            baseColor 0.8 0.8 0.8
            roughness 0.1
          }
          geometry Sphere {
            radius 0.01
          }
        }
      ]
      name "rear_caster"
      boundingObject USE CASTER_SHAPE
      physics Physics {
        mass 0.02
      }
    }
    Solid {
      translation 0.057 0 0.01
      children [
        Pose {
          translation 0 0 0.017
          children [
            Shape {
              appearance PBRAppearance {
                baseColor 0.5 0.5 0.5
                metalness 0.8
              }
              geometry Cylinder {
                height 0.034
                radius 0.012
              }
            }
          ]
        }
        USE CASTER_SHAPE
      ]
      name "front_caster"
      boundingObject USE CASTER_SHAPE
      physics Physics {
        mass 0.02
      }
    }
  ]
  name "JetBot"
  model "Waveshare JetBot ROS AI Kit"
  boundingObject Group {
    children [
      Pose {
        translation 0 0 0.06
        children [
          Box {
            size 0.15 0.11 0.08
          }
        ]
      }
    ]
  }
  physics Physics {
    density -1
    mass 1.2
    centerOfMass [
      0 0 0.05
    ]
  }
  controller "robot_test"
  linearVelocity -0.16191596748211418 -0.0142083202377667 0.00010563086480303068
  angularVelocity 0.0012870330104065913 -0.0009408547682116558 -0.00016772726586217882
}
