#VRML_SIM R2025a utf8

EXTERNPROTO "https://raw.githubusercontent.com/cyberbotics/webots/R2023b/projects/objects/backgrounds/protos/TexturedBackground.proto"
EXTERNPROTO "https://raw.githubusercontent.com/cyberbotics/webots/R2023b/projects/objects/backgrounds/protos/TexturedBackgroundLight.proto"
EXTERNPROTO "https://raw.githubusercontent.com/cyberbotics/webots/R2023b/projects/objects/floors/protos/RectangleArena.proto"

WorldInfo {
}
Viewpoint {
  orientation 0.2889471961739723 0.011088887714205072 -0.9572808127150891 3.045099441146794
  position 2.5944202993064094 0.6729119460990555 1.9240187257265253
}
TexturedBackground {
}
TexturedBackgroundLight {
}
RectangleArena {
  wallHeight 0.2
}
Robot {
  translation 0.3060722175711111 -0.001073170681915115 -0.0004393841396107684
  rotation 1.483238968494154e-08 -1.081076171071388e-08 0.9999999999999999 -1.5522329306386533
  children [
    Solid {
      translation 0 0 0.045
      children [
        Shape {
          appearance PBRAppearance {
            baseColor 0.05 0.05 0.05
            roughness 0.2
            metalness 0.9
          }
          geometry Box {
            size 0.14 0.11 0.002
          }
        }
      ]
      name "solid(1)"
      boundingObject Box {
        size 0.14 0.11 0.002
      }
      physics Physics {
        mass 0.2
      }
    }
    Pose {
      translation 0.06 0.05 0.065
      children [
        DEF STANDOFF Shape {
          appearance PBRAppearance {
            baseColor 0.8 0.6 0.2
          }
          geometry Cylinder {
            height 0.04
            radius 0.003
          }
        }
      ]
    }
    Pose {
      translation 0.06 -0.05 0.065
      children [
        USE STANDOFF
      ]
    }
    Pose {
      translation -0.06 0.05 0.065
      children [
        USE STANDOFF
      ]
    }
    Pose {
      translation -0.06 -0.05 0.065
      children [
        USE STANDOFF
      ]
    }
    Solid {
      translation 0 0 0.085
      children [
        Shape {
          appearance PBRAppearance {
            baseColor 0.05 0.05 0.05
            roughness 0.2
            metalness 0.9
          }
          geometry Box {
            size 0.14 0.11 0.002
          }
        }
      ]
      boundingObject Box {
        size 0.14 0.11 0.002
      }
      physics Physics {
        mass 0.1
      }
    }
    Pose {
      translation -0.05 -3.67318e-08 0.065
      rotation 0 0 1 1.5708
      children [
        Shape {
          appearance PBRAppearance {
            baseColor 0.1 0.2 0.9
            metalness 0.1
          }
          geometry Cylinder {
            height 0.04
            radius 0.018
          }
        }
        Pose {
          translation 0 -0.018 -0.018
          children [
            Shape {
              appearance PBRAppearance {
                baseColor 0.1 0.1 0.1
              }
              geometry Box {
                size 0.06 0.01 0.005
              }
            }
          ]
        }
      ]
    }
    Pose {
      translation 0.01 0 0.087
      children [
        Shape {
          appearance PBRAppearance {
            baseColor 0 0.35 0
            roughness 0.6
          }
          geometry Box {
            size 0.1 0.08 0.0015
          }
        }
        Pose {
          translation 0 0 0.013
          children [
            Shape {
              appearance PBRAppearance {
                baseColor 0.75 0.75 0.75
                metalness 0.9
              }
              geometry Box {
                size 0.06 0.04 0.025
              }
            }
          ]
        }
        Pose {
          translation 0.045 -0.015 0.006
          children [
            DEF USB_PORT Shape {
              appearance PBRAppearance {
                baseColor 0.8 0.8 0.8
              }
              geometry Box {
                size 0.01 0.015 0.01
              }
            }
          ]
        }
        Pose {
          translation 0.045 0.015 0.006
          children [
            USE USB_PORT
          ]
        }
        Pose {
          translation 0.045 0.035 0.008
          children [
            Shape {
              appearance PBRAppearance {
                baseColor 0.8 0.8 0.8
              }
              geometry Box {
                size 0.01 0.02 0.015
              }
            }
          ]
        }
      ]
    }
    Pose {
      translation -0.03 0 0.086
      children [
        Pose {
          translation 0 0 0.025
          children [
            Shape {
              appearance PBRAppearance {
                baseColor 0.1 0.1 0.1
              }
              geometry Cylinder {
                height 0.05
                radius 0.01
              }
            }
          ]
        }
        Pose {
          translation 0 0 0.05
          children [
            Lidar {
              children [
                Shape {
                  appearance PBRAppearance {
                    baseColor 0.1 0.1 0.1
                    roughness 0.6
                  }
                  geometry Cylinder {
                    height 0.02
                    radius 0.03
                  }
                }
                Pose {
                  translation 0 0 0.025
                  children [
                    Shape {
                      appearance PBRAppearance {
                        baseColor 0.05 0.05 0.05
                        roughness 0.5
                      }
                      geometry Cylinder {
                        height 0.02
                        radius 0.03
                      }
                    }
                    Pose {
                      translation 0.025 0.005 0
                      children [
                        Shape {
                          appearance PBRAppearance {
                            baseColor 0.1 0.1 0.8
                            metalness 0.5
                            emissiveColor 0 0 0.1
                          }
                          geometry Box {
                            size 0.01 0.01 0.01
                          }
                        }
                      ]
                    }
                    Pose {
                      translation 0.025 -0.005 0
                      children [
                        Shape {
                          appearance PBRAppearance {
                            baseColor 0.1 0.1 0.8
                            metalness 0.5
                          }
                          geometry Box {
                            size 0.01 0.01 0.01
                          }
                        }
                      ]
                    }
                  ]
                }
              ]
              horizontalResolution 720
              fieldOfView 6.28318
              numberOfLayers 5
              minRange 0.12
              maxRange 8
              type "rotating"
              noise 0.005
            }
          ]
        }
      ]
    }
    Pose {
      translation 0.065 0 0.086
      children [
        Pose {
          translation -0.005 0 0.005
          children [
            Shape {
              appearance PBRAppearance {
                baseColor 0.1 0.1 0.1
              }
              geometry Box {
                size 0.01 0.03 0.01
              }
            }
          ]
        }
        Pose {
          translation 0 0 0.015
          children [
            Camera {
              rotation 0.579145126877391 0.5753141260381066 0.5775851265356307 0.000395586
              children [
                Shape {
                  appearance PBRAppearance {
                    baseColor 0 0.3 0
                  }
                  geometry Box {
                    size 0.005 0.03 0.03
                  }
                }
                Pose {
                  translation 0.005 0 0
                  rotation 0 0 1 1.5708
                  children [
                    Shape {
                      appearance PBRAppearance {
                        baseColor 0.1 0.1 0.1
                        roughness 0.1
                      }
                      geometry Cylinder {
                        height 0.01
                        radius 0.008
                      }
                    }
                  ]
                }
              ]
              fieldOfView 2.5
              width 1280
              height 720
            }
          ]
        }
      ]
    }
    HingeJoint {
      jointParameters HingeJointParameters {
        position 490.4006254455058
        axis 0 1 0
        anchor 0 0.07 0.0325
      }
      device [
        RotationalMotor {
          name "left_wheel_motor"
          maxVelocity 15
          maxTorque 0.5
        }
        PositionSensor {
          name "left_wheel_sensor"
        }
      ]
      endPoint Solid {
        translation 0 0.075 0.0325
        rotation 0.9761195877510919 0.15360725417125976 -0.15360781840324542 1.5949678175545972
        children [
          Shape {
            appearance PBRAppearance {
              baseColor 0.95 0.8 0.1
              roughness 0.4
              metalness 0.1
            }
            geometry Cylinder {
              height 0.026
              radius 0.028
            }
          }
          Shape {
            appearance PBRAppearance {
              baseColor 0.15 0.15 0.15
              roughness 0.9
              metalness 0
            }
            geometry Cylinder {
              height 0.025
              radius 0.0325
            }
          }
          Pose {
            translation 0 0.014 0
            children [
              Shape {
                appearance PBRAppearance {
                  baseColor 0.7 0.7 0.7
                }
                geometry Cylinder {
                  height 0.005
                  radius 0.004
                }
              }
            ]
          }
        ]
        name "left wheel"
        boundingObject Cylinder {
          height 0.026
          radius 0.0325
        }
        physics Physics {
          density -1
          mass 0.06
        }
        linearVelocity 0.0030018307878052443 -0.1624582533471795 -1.0070188475950782e-08
        angularVelocity 4.999137652614549 0.092811209990033 7.292982919553334e-07
      }
    }
    HingeJoint {
      jointParameters HingeJointParameters {
        position 381.0233293042146
        axis 0 1 0
        anchor 0 -0.07 0.0325
      }
      device [
        RotationalMotor {
          name "right_wheel_motor"
          maxVelocity 15
          maxTorque 0.5
        }
        PositionSensor {
          name "right_wheel_sensor"
        }
      ]
      endPoint Solid {
        translation 0 -0.075 0.0325
        rotation -0.31977048219972726 0.6699789329171046 -0.6699813938916601 3.76057998711134
        children [
          Shape {
            appearance PBRAppearance {
              baseColor 0.95 0.8 0.1
              roughness 0.4
              metalness 0.1
            }
            geometry Cylinder {
              height 0.026
              radius 0.028
            }
          }
          Shape {
            appearance PBRAppearance {
              baseColor 0.15 0.15 0.15
              roughness 0.9
              metalness 0
            }
            geometry Cylinder {
              height 0.025
              radius 0.0325
            }
          }
          Pose {
            translation 0 -0.014 0
            children [
              Shape {
                appearance PBRAppearance {
                  baseColor 0.7 0.7 0.7
                }
                geometry Cylinder {
                  height 0.005
                  radius 0.004
                }
              }
            ]
          }
        ]
        name "right wheel"
        boundingObject Cylinder {
          height 0.026
          radius 0.0325
        }
        physics Physics {
          density -1
          mass 0.06
        }
        linearVelocity 0.0030034471590216546 -0.16245823238615345 9.61097062663964e-09
        angularVelocity 4.9991376470311435 0.09281154233830703 4.1760203045139994e-07
      }
    }
    Solid {
      translation -0.057 0 0.01
      children [
        Pose {
          translation 0 0 0.017
          children [
            Shape {
              appearance PBRAppearance {
                baseColor 0.5 0.5 0.5
                metalness 0.8
              }
              geometry Cylinder {
                height 0.034
                radius 0.012
              }
            }
          ]
        }
        DEF CASTER_SHAPE Shape {
          appearance PBRAppearance {
            baseColor 0.8 0.8 0.8
            roughness 0.1
          }
          geometry Sphere {
            radius 0.01
          }
        }
      ]
      name "rear_caster"
      boundingObject USE CASTER_SHAPE
      physics Physics {
        mass 0.02
      }
    }
    Solid {
      translation 0.057 0 0.01
      children [
        Pose {
          translation 0 0 0.017
          children [
            Shape {
              appearance PBRAppearance {
                baseColor 0.5 0.5 0.5
                metalness 0.8
              }
              geometry Cylinder {
                height 0.034
                radius 0.012
              }
            }
          ]
        }
        USE CASTER_SHAPE
      ]
      name "front_caster"
      boundingObject USE CASTER_SHAPE
      physics Physics {
        mass 0.02
      }
    }
  ]
  name "JetBot"
  model "Waveshare JetBot ROS AI Kit"
  boundingObject Group {
    children [
      Pose {
        translation 0 0 0.06
        children [
          Box {
            size 0.15 0.11 0.08
          }
        ]
      }
    ]
  }
  physics Physics {
    density -1
    mass 1.2
    centerOfMass [
      0 0 0.05
    ]
  }
  controller "robot_test"
  linearVelocity 0.0030026413921497466 -0.16245824359100608 4.2834195852299533e-10
  angularVelocity 2.573812274614986e-08 1.3578006815537189e-07 2.5525199406668515e-07
}
