#VRML_SIM R2025a utf8

EXTERNPROTO "https://raw.githubusercontent.com/cyberbotics/webots/R2023b/projects/objects/backgrounds/protos/TexturedBackground.proto"
EXTERNPROTO "https://raw.githubusercontent.com/cyberbotics/webots/R2023b/projects/objects/backgrounds/protos/TexturedBackgroundLight.proto"
EXTERNPROTO "https://raw.githubusercontent.com/cyberbotics/webots/R2023b/projects/objects/floors/protos/RectangleArena.proto"
EXTERNPROTO "https://raw.githubusercontent.com/cyberbotics/webots/R2025a/projects/objects/balls/protos/Ball.proto"
EXTERNPROTO "https://raw.githubusercontent.com/cyberbotics/webots/R2025a/projects/objects/factory/containers/protos/WoodenBox.proto"

WorldInfo {
}
Viewpoint {
  orientation 0.3613982741147102 -0.48306935867512607 -0.7975182017835778 4.758030173028095
  position -2.852644268568829 -7.2677502587382055 8.202161209350677
}
TexturedBackground {
}
TexturedBackgroundLight {
}
RectangleArena {
  floorSize 5 5
  wallHeight 0.2
}
Ball {
  translation -0.08267399993405694 -0.5273015055964545 0.09991367200000001
  rotation 1.4235275491123422e-08 1.6536600857195032e-08 0.9999999999999998 -2.482464231328515
  color 1 0 0
  radius 0.1
}
Robot {
  translation -1.83755 -0.253376 -0.000439858
  rotation -9.883811546057755e-05 8.092786992078288e-05 -0.9999999918408533 -1.9078724928138797
  children [
    Solid {
      translation 0 0 0.045
      children [
        Shape {
          appearance PBRAppearance {
            baseColor 0.05 0.05 0.05
            roughness 0.2
            metalness 0.9
          }
          geometry Box {
            size 0.14 0.11 0.002
          }
        }
      ]
      name "solid(1)"
      boundingObject Box {
        size 0.14 0.11 0.002
      }
      physics Physics {
        mass 0.2
      }
    }
    Pose {
      translation 0.06 0.05 0.065
      children [
        DEF STANDOFF Shape {
          appearance PBRAppearance {
            baseColor 0.8 0.6 0.2
          }
          geometry Cylinder {
            height 0.04
            radius 0.003
          }
        }
      ]
    }
    Pose {
      translation 0.06 -0.05 0.065
      children [
        USE STANDOFF
      ]
    }
    Pose {
      translation -0.06 0.05 0.065
      children [
        USE STANDOFF
      ]
    }
    Pose {
      translation -0.06 -0.05 0.065
      children [
        USE STANDOFF
      ]
    }
    Solid {
      translation 0 0 0.085
      children [
        Shape {
          appearance PBRAppearance {
            baseColor 0.05 0.05 0.05
            roughness 0.2
            metalness 0.9
          }
          geometry Box {
            size 0.14 0.11 0.002
          }
        }
      ]
      boundingObject Box {
        size 0.14 0.11 0.002
      }
      physics Physics {
        mass 0.1
      }
    }
    Pose {
      translation -0.05 -3.67318e-08 0.065
      rotation 0 0 1 1.5708
      children [
        Shape {
          appearance PBRAppearance {
            baseColor 0.1 0.2 0.9
            metalness 0.1
          }
          geometry Cylinder {
            height 0.04
            radius 0.018
          }
        }
        Pose {
          translation 0 -0.018 -0.018
          children [
            Shape {
              appearance PBRAppearance {
                baseColor 0.1 0.1 0.1
              }
              geometry Box {
                size 0.06 0.01 0.005
              }
            }
          ]
        }
      ]
    }
    Pose {
      translation 0.01 0 0.087
      children [
        Shape {
          appearance PBRAppearance {
            baseColor 0 0.35 0
            roughness 0.6
          }
          geometry Box {
            size 0.1 0.08 0.0015
          }
        }
        Pose {
          translation 0 0 0.013
          children [
            Shape {
              appearance PBRAppearance {
                baseColor 0.75 0.75 0.75
                metalness 0.9
              }
              geometry Box {
                size 0.06 0.04 0.025
              }
            }
          ]
        }
        Pose {
          translation 0.045 -0.015 0.006
          children [
            DEF USB_PORT Shape {
              appearance PBRAppearance {
                baseColor 0.8 0.8 0.8
              }
              geometry Box {
                size 0.01 0.015 0.01
              }
            }
          ]
        }
        Pose {
          translation 0.045 0.015 0.006
          children [
            USE USB_PORT
          ]
        }
        Pose {
          translation 0.045 0.035 0.008
          children [
            Shape {
              appearance PBRAppearance {
                baseColor 0.8 0.8 0.8
              }
              geometry Box {
                size 0.01 0.02 0.015
              }
            }
          ]
        }
      ]
    }
    Pose {
      translation -0.03 0 0.086
      children [
        Pose {
          translation 0 0 0.025
          children [
            Shape {
              appearance PBRAppearance {
                baseColor 0.1 0.1 0.1
              }
              geometry Cylinder {
                height 0.05
                radius 0.01
              }
            }
          ]
        }
        Pose {
          translation 0 0 0.05
          children [
            Lidar {
              rotation 0 0 1 -3.010695613280012
              children [
                Shape {
                  appearance PBRAppearance {
                    baseColor 0.1 0.1 0.1
                    roughness 0.6
                  }
                  geometry Cylinder {
                    height 0.02
                    radius 0.03
                  }
                }
                Pose {
                  translation 0 0 0.025
                  children [
                    Shape {
                      appearance PBRAppearance {
                        baseColor 0.05 0.05 0.05
                        roughness 0.5
                      }
                      geometry Cylinder {
                        height 0.02
                        radius 0.03
                      }
                    }
                    Pose {
                      translation 0.025 0.005 0
                      children [
                        Shape {
                          appearance PBRAppearance {
                            baseColor 0.1 0.1 0.8
                            metalness 0.5
                            emissiveColor 0 0 0.1
                          }
                          geometry Box {
                            size 0.01 0.01 0.01
                          }
                        }
                      ]
                    }
                    Pose {
                      translation 0.025 -0.005 0
                      children [
                        Shape {
                          appearance PBRAppearance {
                            baseColor 0.1 0.1 0.8
                            metalness 0.5
                          }
                          geometry Box {
                            size 0.01 0.01 0.01
                          }
                        }
                      ]
                    }
                  ]
                }
              ]
              horizontalResolution 720
              fieldOfView 6.28318
              numberOfLayers 5
              minRange 0.12
              maxRange 8
              noise 0.005
            }
          ]
        }
      ]
    }
    Pose {
      translation 0.065 0 0.086
      children [
        Pose {
          translation -0.005 0 0.005
          children [
            Shape {
              appearance PBRAppearance {
                baseColor 0.1 0.1 0.1
              }
              geometry Box {
                size 0.01 0.03 0.01
              }
            }
          ]
        }
        Pose {
          translation 0 0 0.015
          children [
            Camera {
              rotation 0.579145126877391 0.5753141260381066 0.5775851265356307 0.000395586
              children [
                Shape {
                  appearance PBRAppearance {
                    baseColor 0 0.3 0
                  }
                  geometry Box {
                    size 0.005 0.03 0.03
                  }
                }
                Pose {
                  translation 0.005 0 0
                  rotation 0 0 1 1.5708
                  children [
                    Shape {
                      appearance PBRAppearance {
                        baseColor 0.1 0.1 0.1
                        roughness 0.1
                      }
                      geometry Cylinder {
                        height 0.01
                        radius 0.008
                      }
                    }
                  ]
                }
              ]
              fieldOfView 2.5
              width 1280
              height 720
            }
          ]
        }
      ]
    }
    HingeJoint {
      jointParameters HingeJointParameters {
        position 1768.7812128909447
        axis 0 1 0
        anchor 0 0.07 0.0325
      }
      device [
        RotationalMotor {
          name "left_wheel_motor"
          maxVelocity 15
          maxTorque 0.5
        }
        PositionSensor {
          name "left_wheel_sensor"
        }
      ]
      endPoint Solid {
        translation 0 0.075 0.0325
        rotation 0.022823511797463385 -0.7069212884110763 0.7069238850827257 3.0959537211397623
        children [
          Shape {
            appearance PBRAppearance {
              baseColor 0.95 0.8 0.1
              roughness 0.4
              metalness 0.1
            }
            geometry Cylinder {
              height 0.026
              radius 0.028
            }
          }
          Shape {
            appearance PBRAppearance {
              baseColor 0.15 0.15 0.15
              roughness 0.9
              metalness 0
            }
            geometry Cylinder {
              height 0.025
              radius 0.0325
            }
          }
          Pose {
            translation 0 0.014 0
            children [
              Shape {
                appearance PBRAppearance {
                  baseColor 0.7 0.7 0.7
                }
                geometry Cylinder {
                  height 0.005
                  radius 0.004
                }
              }
            ]
          }
        ]
        name "left wheel"
        boundingObject Cylinder {
          height 0.026
          radius 0.0325
        }
        physics Physics {
          density -1
          mass 0.06
        }
      }
    }
    HingeJoint {
      jointParameters HingeJointParameters {
        position 1625.5989453327127
        axis 0 1 0
        anchor 0 -0.07 0.0325
      }
      device [
        RotationalMotor {
          name "right_wheel_motor"
          maxVelocity 15
          maxTorque 0.5
        }
        PositionSensor {
          name "right_wheel_sensor"
        }
      ]
      endPoint Solid {
        translation 0 -0.075 0.0325
        rotation -0.5099983862131116 0.6082347113777403 -0.608236945552684 4.084818254647296
        children [
          Shape {
            appearance PBRAppearance {
              baseColor 0.95 0.8 0.1
              roughness 0.4
              metalness 0.1
            }
            geometry Cylinder {
              height 0.026
              radius 0.028
            }
          }
          Shape {
            appearance PBRAppearance {
              baseColor 0.15 0.15 0.15
              roughness 0.9
              metalness 0
            }
            geometry Cylinder {
              height 0.025
              radius 0.0325
            }
          }
          Pose {
            translation 0 -0.014 0
            children [
              Shape {
                appearance PBRAppearance {
                  baseColor 0.7 0.7 0.7
                }
                geometry Cylinder {
                  height 0.005
                  radius 0.004
                }
              }
            ]
          }
        ]
        name "right wheel"
        boundingObject Cylinder {
          height 0.026
          radius 0.0325
        }
        physics Physics {
          density -1
          mass 0.06
        }
      }
    }
    Solid {
      translation -0.057 0 0.01
      children [
        Pose {
          translation 0 0 0.017
          children [
            Shape {
              appearance PBRAppearance {
                baseColor 0.5 0.5 0.5
                metalness 0.8
              }
              geometry Cylinder {
                height 0.034
                radius 0.012
              }
            }
          ]
        }
        DEF CASTER_SHAPE Shape {
          appearance PBRAppearance {
            baseColor 0.8 0.8 0.8
            roughness 0.1
          }
          geometry Sphere {
            radius 0.01
          }
        }
      ]
      name "rear_caster"
      boundingObject USE CASTER_SHAPE
      physics Physics {
        mass 0.02
      }
    }
    Solid {
      translation 0.057 0 0.01
      children [
        Pose {
          translation 0 0 0.017
          children [
            Shape {
              appearance PBRAppearance {
                baseColor 0.5 0.5 0.5
                metalness 0.8
              }
              geometry Cylinder {
                height 0.034
                radius 0.012
              }
            }
          ]
        }
        USE CASTER_SHAPE
      ]
      name "front_caster"
      boundingObject USE CASTER_SHAPE
      physics Physics {
        mass 0.02
      }
    }
  ]
  name "JetBot"
  model "Waveshare JetBot ROS AI Kit"
  boundingObject Group {
    children [
      Pose {
        translation 0 0 0.06
        children [
          Box {
            size 0.15 0.11 0.08
          }
        ]
      }
    ]
  }
  physics Physics {
    density -1
    mass 1.2
    centerOfMass [
      0 0 0.05
    ]
  }
  controller "robot_test"
}
WoodenBox {
  translation -1.09 0 0.3
}
WoodenBox {
  translation -0.1 0.69 0.3
  name "wooden box(1)"
}
